Workbook
Name Lista_Categorias: '0_Listas_y_Apoyo'!$A$4:$A$13
Name Lista_MetodosPago: '0_Listas_y_Apoyo'!$B$4:$B$8
Name Lista_Proveedores: '0_Listas_y_Apoyo'!$C$4:$C$9
Name Lista_SKU: '2_Control_de_Stock'!$A$11:$A$210

Sheet 0_Listas_y_Apoyo
A1: PARÁMETROS Y LISTAS MAESTRAS DAMABIS | H1: TABLA DE APOYO · RANKING DE PRODUCTOS (no editar)
A3: Categorías | B3: Métodos de Pago | C3: Proveedores | D3: Estados de Stock | H3: Código/SKU | I3: Descripción | J3: Unidades Mes | K3: Ingresos Mes | L3: Ganancia Mes | M3: Índice Ranking
A4: Libros | B4: Efectivo | C4: Distribuidora Lima Papel SAC | D4: 🟢 OK | H4: =IF('2_Control_de_Stock'!$A$11="","",'2_Control_de_Stock'!$A$11) | I4: =IF('2_Control_de_Stock'!$A$11="","",'2_Control_de_Stock'!$B$11) | J4: =IF($H4="","",SUMIFS('3_Ventas_Diarias'!$E$11:$E$610,'3_Ventas_Diarias'!$C$11:$C$610,$H4,'3_Ventas_Diarias'!$A$11:$A$610,">="&'4_Dashboard_DAMABIS'!$P$5,'3_Ventas_Diarias'!$A$11:$A$610,"<="&'4_Dashboard_DAMABIS'!$P$6)) | K4: =IF($H4="","",SUMIFS('3_Ventas_Diarias'!$G$11:$G$610,'3_Ventas_Diarias'!$C$11:$C$610,$H4,'3_Ventas_Diarias'!$A$11:$A$610,">="&'4_Dashboard_DAMABIS'!$P$5,'3_Ventas_Diarias'!$A$11:$A$610,"<="&'4_Dashboard_DAMABIS'!$P$6)) | L4: =IF($H4="","",SUMIFS('3_Ventas_Diarias'!$J$11:$J$610,'3_Ventas_Diarias'!$C$11:$C$610,$H4,'3_Ventas_Diarias'!$A$11:$A$610,">="&'4_Dashboard_DAMABIS'!$P$5,'3_Ventas_Diarias'!$A$11:$A$610,"<="&'4_Dashboard_DAMABIS'!$P$6)) | M4: =IF($H4="","",N($K4)+ROW()/1000000)
A5: Papelería | B5: Tarjeta | C5: Importadora Kawaii Perú EIRL | D5: 🟡 VIGILAR | H5: =IF('2_Control_de_Stock'!$A$12="","",'2_Control_de_Stock'!$A$12) | I5: =IF('2_Control_de_Stock'!$A$12="","",'2_Control_de_Stock'!$B$12) | J5: =IF($H5="","",SUMIFS('3_Ventas_Diarias'!$E$11:$E$610,'3_Ventas_Diarias'!$C$11:$C$610,$H5,'3_Ventas_Diarias'!$A$11:$A$610,">="&'4_Dashboard_DAMABIS'!$P$5,'3_Ventas_Diarias'!$A$11:$A$610,"<="&'4_Dashboard_DAMABIS'!$P$6)) | K5: =IF($H5="","",SUMIFS('3_Ventas_Diarias'!$G$11:$G$610,'3_Ventas_Diarias'!$C$11:$C$610,$H5,'3_Ventas_Diarias'!$A$11:$A$610,">="&'4_Dashboard_DAMABIS'!$P$5,'3_Ventas_Diarias'!$A$11:$A$610,"<="&'4_Dashboard_DAMABIS'!$P$6)) | L5: =IF($H5="","",SUMIFS('3_Ventas_Diarias'!$J$11:$J$610,'3_Ventas_Diarias'!$C$11:$C$610,$H5,'3_Ventas_Diarias'!$A$11:$A$610,">="&'4_Dashboard_DAMABIS'!$P$5,'3_Ventas_Diarias'!$A$11:$A$610,"<="&'4_Dashboard_DAMABIS'!$P$6)) | M5: =IF($H5="","",N($K5)+ROW()/1000000)
A6: Arte | B6: Transferencia | C6: Editorial Andina SAC | D6: 🟠 REPONER | H6: =IF('2_Control_de_Stock'!$A$13="","",'2_Control_de_Stock'!$A$13) | I6: =IF('2_Control_de_Stock'!$A$13="","",'2_Control_de_Stock'!$B$13) | J6: =IF($H6="","",SUMIFS('3_Ventas_Diarias'!$E$11:$E$610,'3_Ventas_Diarias'!$C$11:$C$610,$H6,'3_Ventas_Diarias'!$A$11:$A$610,">="&'4_Dashboard_DAMABIS'!$P$5,'3_Ventas_Diarias'!$A$11:$A$610,"<="&'4_Dashboard_DAMABIS'!$P$6)) | K6: =IF($H6="","",SUMIFS('3_Ventas_Diarias'!$G$11:$G$610,'3_Ventas_Diarias'!$C$11:$C$610,$H6,'3_Ventas_Diarias'!$A$11:$A$610,">="&'4_Dashboard_DAMABIS'!$P$5,'3_Ventas_Diarias'!$A$11:$A$610,"<="&'4_Dashboard_DAMABIS'!$P$6)) | L6: =IF($H6="","",SUMIFS('3_Ventas_Diarias'!$J$11:$J$610,'3_Ventas_Diarias'!$C$11:$C$610,$H6,'3_Ventas_Diarias'!$A$11:$A$610,">="&'4_Dashboard_DAMABIS'!$P$5,'3_Ventas_Diarias'!$A$11:$A$610,"<="&'4_Dashboard_DAMABIS'!$P$6)) | M6: =IF($H6="","",N($K6)+ROW()/1000000)
A7: Kawaii/Escolar | B7: Yape/Plin | C7: Arte & Color Distribuciones | D7: 🔴 SIN STOCK | H7: =IF('2_Control_de_Stock'!$A$14="","",'2_Control_de_Stock'!$A$14) | I7: =IF('2_Control_de_Stock'!$A$14="","",'2_Control_de_Stock'!$B$14) | J7: =IF($H7="","",SUMIFS('3_Ventas_Diarias'!$E$11:$E$610,'3_Ventas_Diarias'!$C$11:$C$610,$H7,'3_Ventas_Diarias'!$A$11:$A$610,">="&'4_Dashboard_DAMABIS'!$P$5,'3_Ventas_Diarias'!$A$11:$A$610,"<="&'4_Dashboard_DAMABIS'!$P$6)) | K7: =IF($H7="","",SUMIFS('3_Ventas_Diarias'!$G$11:$G$610,'3_Ventas_Diarias'!$C$11:$C$610,$H7,'3_Ventas_Diarias'!$A$11:$A$610,">="&'4_Dashboard_DAMABIS'!$P$5,'3_Ventas_Diarias'!$A$11:$A$610,"<="&'4_Dashboard_DAMABIS'!$P$6)) | L7: =IF($H7="","",SUMIFS('3_Ventas_Diarias'!$J$11:$J$610,'3_Ventas_Diarias'!$C$11:$C$610,$H7,'3_Ventas_Diarias'!$A$11:$A$610,">="&'4_Dashboard_DAMABIS'!$P$5,'3_Ventas_Diarias'!$A$11:$A$610,"<="&'4_Dashboard_DAMABIS'!$P$6)) | M7: =IF($H7="","",N($K7)+ROW()/1000000)
A8: Escritura | B8: Crédito | C8: Faber Perú SA | H8: =IF('2_Control_de_Stock'!$A$15="","",'2_Control_de_Stock'!$A$15) | I8: =IF('2_Control_de_Stock'!$A$15="","",'2_Control_de_Stock'!$B$15) | J8: =IF($H8="","",SUMIFS('3_Ventas_Diarias'!$E$11:$E$610,'3_Ventas_Diarias'!$C$11:$C$610,$H8,'3_Ventas_Diarias'!$A$11:$A$610,">="&'4_Dashboard_DAMABIS'!$P$5,'3_Ventas_Diarias'!$A$11:$A$610,"<="&'4_Dashboard_DAMABIS'!$P$6)) | K8: =IF($H8="","",SUMIFS('3_Ventas_Diarias'!$G$11:$G$610,'3_Ventas_Diarias'!$C$11:$C$610,$H8,'3_Ventas_Diarias'!$A$11:$A$610,">="&'4_Dashboard_DAMABIS'!$P$5,'3_Ventas_Diarias'!$A$11:$A$610,"<="&'4_Dashboard_DAMABIS'!$P$6)) | L8: =IF($H8="","",SUMIFS('3_Ventas_Diarias'!$J$11:$J$610,'3_Ventas_Diarias'!$C$11:$C$610,$H8,'3_Ventas_Diarias'!$A$11:$A$610,">="&'4_Dashboard_DAMABIS'!$P$5,'3_Ventas_Diarias'!$A$11:$A$610,"<="&'4_Dashboard_DAMABIS'!$P$6)) | M8: =IF($H8="","",N($K8)+ROW()/1000000)
A9: Cuadernos | C9: Mayorista Mesa Redonda | H9: =IF('2_Control_de_Stock'!$A$16="","",'2_Control_de_Stock'!$A$16) | I9: =IF('2_Control_de_Stock'!$A$16="","",'2_Control_de_Stock'!$B$16) | J9: =IF($H9="","",SUMIFS('3_Ventas_Diarias'!$E$11:$E$610,'3_Ventas_Diarias'!$C$11:$C$610,$H9,'3_Ventas_Diarias'!$A$11:$A$610,">="&'4_Dashboard_DAMABIS'!$P$5,'3_Ventas_Diarias'!$A$11:$A$610,"<="&'4_Dashboard_DAMABIS'!$P$6)) | K9: =IF($H9="","",SUMIFS('3_Ventas_Diarias'!$G$11:$G$610,'3_Ventas_Diarias'!$C$11:$C$610,$H9,'3_Ventas_Diarias'!$A$11:$A$610,">="&'4_Dashboard_DAMABIS'!$P$5,'3_Ventas_Diarias'!$A$11:$A$610,"<="&'4_Dashboard_DAMABIS'!$P$6)) | L9: =IF($H9="","",SUMIFS('3_Ventas_Diarias'!$J$11:$J$610,'3_Ventas_Diarias'!$C$11:$C$610,$H9,'3_Ventas_Diarias'!$A$11:$A$610,">="&'4_Dashboard_DAMABIS'!$P$5,'3_Ventas_Diarias'!$A$11:$A$610,"<="&'4_Dashboard_DAMABIS'!$P$6)) | M9: =IF($H9="","",N($K9)+ROW()/1000000)
A10: Mochilas y Loncheras | H10: =IF('2_Control_de_Stock'!$A$17="","",'2_Control_de_Stock'!$A$17) | I10: =IF('2_Control_de_Stock'!$A$17="","",'2_Control_de_Stock'!$B$17) | J10: =IF($H10="","",SUMIFS('3_Ventas_Diarias'!$E$11:$E$610,'3_Ventas_Diarias'!$C$11:$C$610,$H10,'3_Ventas_Diarias'!$A$11:$A$610,">="&'4_Dashboard_DAMABIS'!$P$5,'3_Ventas_Diarias'!$A$11:$A$610,"<="&'4_Dashboard_DAMABIS'!$P$6)) | K10: =IF($H10="","",SUMIFS('3_Ventas_Diarias'!$G$11:$G$610,'3_Ventas_Diarias'!$C$11:$C$610,$H10,'3_Ventas_Diarias'!$A$11:$A$610,">="&'4_Dashboard_DAMABIS'!$P$5,'3_Ventas_Diarias'!$A$11:$A$610,"<="&'4_Dashboard_DAMABIS'!$P$6)) | L10: =IF($H10="","",SUMIFS('3_Ventas_Diarias'!$J$11:$J$610,'3_Ventas_Diarias'!$C$11:$C$610,$H10,'3_Ventas_Diarias'!$A$11:$A$610,">="&'4_Dashboard_DAMABIS'!$P$5,'3_Ventas_Diarias'!$A$11:$A$610,"<="&'4_Dashboard_DAMABIS'!$P$6)) | M10: =IF($H10="","",N($K10)+ROW()/1000000)
A11: Tecnología | H11: =IF('2_Control_de_Stock'!$A$18="","",'2_Control_de_Stock'!$A$18) | I11: =IF('2_Control_de_Stock'!$A$18="","",'2_Control_de_Stock'!$B$18) | J11: =IF($H11="","",SUMIFS('3_Ventas_Diarias'!$E$11:$E$610,'3_Ventas_Diarias'!$C$11:$C$610,$H11,'3_Ventas_Diarias'!$A$11:$A$610,">="&'4_Dashboard_DAMABIS'!$P$5,'3_Ventas_Diarias'!$A$11:$A$610,"<="&'4_Dashboard_DAMABIS'!$P$6)) | K11: =IF($H11="","",SUMIFS('3_Ventas_Diarias'!$G$11:$G$610,'3_Ventas_Diarias'!$C$11:$C$610,$H11,'3_Ventas_Diarias'!$A$11:$A$610,">="&'4_Dashboard_DAMABIS'!$P$5,'3_Ventas_Diarias'!$A$11:$A$610,"<="&'4_Dashboard_DAMABIS'!$P$6)) | L11: =IF($H11="","",SUMIFS('3_Ventas_Diarias'!$J$11:$J$610,'3_Ventas_Diarias'!$C$11:$C$610,$H11,'3_Ventas_Diarias'!$A$11:$A$610,">="&'4_Dashboard_DAMABIS'!$P$5,'3_Ventas_Diarias'!$A$11:$A$610,"<="&'4_Dashboard_DAMABIS'!$P$6)) | M11: =IF($H11="","",N($K11)+ROW()/1000000)
A12: Manualidades | H12: =IF('2_Control_de_Stock'!$A$19="","",'2_Control_de_Stock'!$A$19) | I12: =IF('2_Control_de_Stock'!$A$19="","",'2_Control_de_Stock'!$B$19) | J12: =IF($H12="","",SUMIFS('3_Ventas_Diarias'!$E$11:$E$610,'3_Ventas_Diarias'!$C$11:$C$610,$H12,'3_Ventas_Diarias'!$A$11:$A$610,">="&'4_Dashboard_DAMABIS'!$P$5,'3_Ventas_Diarias'!$A$11:$A$610,"<="&'4_Dashboard_DAMABIS'!$P$6)) | K12: =IF($H12="","",SUMIFS('3_Ventas_Diarias'!$G$11:$G$610,'3_Ventas_Diarias'!$C$11:$C$610,$H12,'3_Ventas_Diarias'!$A$11:$A$610,">="&'4_Dashboard_DAMABIS'!$P$5,'3_Ventas_Diarias'!$A$11:$A$610,"<="&'4_Dashboard_DAMABIS'!$P$6)) | L12: =IF($H12="","",SUMIFS('3_Ventas_Diarias'!$J$11:$J$610,'3_Ventas_Diarias'!$C$11:$C$610,$H12,'3_Ventas_Diarias'!$A$11:$A$610,">="&'4_Dashboard_DAMABIS'!$P$5,'3_Ventas_Diarias'!$A$11:$A$610,"<="&'4_Dashboard_DAMABIS'!$P$6)) | M12: =IF($H12="","",N($K12)+ROW()/1000000)
A13: Oficina | H13: =IF('2_Control_de_Stock'!$A$20="","",'2_Control_de_Stock'!$A$20) | I13: =IF('2_Control_de_Stock'!$A$20="","",'2_Control_de_Stock'!$B$20) | J13: =IF($H13="","",SUMIFS('3_Ventas_Diarias'!$E$11:$E$610,'3_Ventas_Diarias'!$C$11:$C$610,$H13,'3_Ventas_Diarias'!$A$11:$A$610,">="&'4_Dashboard_DAMABIS'!$P$5,'3_Ventas_Diarias'!$A$11:$A$610,"<="&'4_Dashboard_DAMABIS'!$P$6)) | K13: =IF($H13="","",SUMIFS('3_Ventas_Diarias'!$G$11:$G$610,'3_Ventas_Diarias'!$C$11:$C$610,$H13,'3_Ventas_Diarias'!$A$11:$A$610,">="&'4_Dashboard_DAMABIS'!$P$5,'3_Ventas_Diarias'!$A$11:$A$610,"<="&'4_Dashboard_DAMABIS'!$P$6)) | L13: =IF($H13="","",SUMIFS('3_Ventas_Diarias'!$J$11:$J$610,'3_Ventas_Diarias'!$C$11:$C$610,$H13,'3_Ventas_Diarias'!$A$11:$A$610,">="&'4_Dashboard_DAMABIS'!$P$5,'3_Ventas_Diarias'!$A$11:$A$610,"<="&'4_Dashboard_DAMABIS'!$P$6)) | M13: =IF($H13="","",N($K13)+ROW()/1000000)
H14: =IF('2_Control_de_Stock'!$A$21="","",'2_Control_de_Stock'!$A$21) | I14: =IF('2_Control_de_Stock'!$A$21="","",'2_Control_de_Stock'!$B$21) | J14: =IF($H14="","",SUMIFS('3_Ventas_Diarias'!$E$11:$E$610,'3_Ventas_Diarias'!$C$11:$C$610,$H14,'3_Ventas_Diarias'!$A$11:$A$610,">="&'4_Dashboard_DAMABIS'!$P$5,'3_Ventas_Diarias'!$A$11:$A$610,"<="&'4_Dashboard_DAMABIS'!$P$6)) | K14: =IF($H14="","",SUMIFS('3_Ventas_Diarias'!$G$11:$G$610,'3_Ventas_Diarias'!$C$11:$C$610,$H14,'3_Ventas_Diarias'!$A$11:$A$610,">="&'4_Dashboard_DAMABIS'!$P$5,'3_Ventas_Diarias'!$A$11:$A$610,"<="&'4_Dashboard_DAMABIS'!$P$6)) | L14: =IF($H14="","",SUMIFS('3_Ventas_Diarias'!$J$11:$J$610,'3_Ventas_Diarias'!$C$11:$C$610,$H14,'3_Ventas_Diarias'!$A$11:$A$610,">="&'4_Dashboard_DAMABIS'!$P$5,'3_Ventas_Diarias'!$A$11:$A$610,"<="&'4_Dashboard_DAMABIS'!$P$6)) | M14: =IF($H14="","",N($K14)+ROW()/1000000)
H15: =IF('2_Control_de_Stock'!$A$22="","",'2_Control_de_Stock'!$A$22) | I15: =IF('2_Control_de_Stock'!$A$22="","",'2_Control_de_Stock'!$B$22) | J15: =IF($H15="","",SUMIFS('3_Ventas_Diarias'!$E$11:$E$610,'3_Ventas_Diarias'!$C$11:$C$610,$H15,'3_Ventas_Diarias'!$A$11:$A$610,">="&'4_Dashboard_DAMABIS'!$P$5,'3_Ventas_Diarias'!$A$11:$A$610,"<="&'4_Dashboard_DAMABIS'!$P$6)) | K15: =IF($H15="","",SUMIFS('3_Ventas_Diarias'!$G$11:$G$610,'3_Ventas_Diarias'!$C$11:$C$610,$H15,'3_Ventas_Diarias'!$A$11:$A$610,">="&'4_Dashboard_DAMABIS'!$P$5,'3_Ventas_Diarias'!$A$11:$A$610,"<="&'4_Dashboard_DAMABIS'!$P$6)) | L15: =IF($H15="","",SUMIFS('3_Ventas_Diarias'!$J$11:$J$610,'3_Ventas_Diarias'!$C$11:$C$610,$H15,'3_Ventas_Diarias'!$A$11:$A$610,">="&'4_Dashboard_DAMABIS'!$P$5,'3_Ventas_Diarias'!$A$11:$A$610,"<="&'4_Dashboard_DAMABIS'!$P$6)) | M15: =IF($H15="","",N($K15)+ROW()/1000000)
H16: =IF('2_Control_de_Stock'!$A$23="","",'2_Control_de_Stock'!$A$23) | I16: =IF('2_Control_de_Stock'!$A$23="","",'2_Control_de_Stock'!$B$23) | J16: =IF($H16="","",SUMIFS('3_Ventas_Diarias'!$E$11:$E$610,'3_Ventas_Diarias'!$C$11:$C$610,$H16,'3_Ventas_Diarias'!$A$11:$A$610,">="&'4_Dashboard_DAMABIS'!$P$5,'3_Ventas_Diarias'!$A$11:$A$610,"<="&'4_Dashboard_DAMABIS'!$P$6)) | K16: =IF($H16="","",SUMIFS('3_Ventas_Diarias'!$G$11:$G$610,'3_Ventas_Diarias'!$C$11:$C$610,$H16,'3_Ventas_Diarias'!$A$11:$A$610,">="&'4_Dashboard_DAMABIS'!$P$5,'3_Ventas_Diarias'!$A$11:$A$610,"<="&'4_Dashboard_DAMABIS'!$P$6)) | L16: =IF($H16="","",SUMIFS('3_Ventas_Diarias'!$J$11:$J$610,'3_Ventas_Diarias'!$C$11:$C$610,$H16,'3_Ventas_Diarias'!$A$11:$A$610,">="&'4_Dashboard_DAMABIS'!$P$5,'3_Ventas_Diarias'!$A$11:$A$610,"<="&'4_Dashboard_DAMABIS'!$P$6)) | M16: =IF($H16="","",N($K16)+ROW()/1000000)
H17: =IF('2_Control_de_Stock'!$A$24="","",'2_Control_de_Stock'!$A$24) | I17: =IF('2_Control_de_Stock'!$A$24="","",'2_Control_de_Stock'!$B$24) | J17: =IF($H17="","",SUMIFS('3_Ventas_Diarias'!$E$11:$E$610,'3_Ventas_Diarias'!$C$11:$C$610,$H17,'3_Ventas_Diarias'!$A$11:$A$610,">="&'4_Dashboard_DAMABIS'!$P$5,'3_Ventas_Diarias'!$A$11:$A$610,"<="&'4_Dashboard_DAMABIS'!$P$6)) | K17: =IF($H17="","",SUMIFS('3_Ventas_Diarias'!$G$11:$G$610,'3_Ventas_Diarias'!$C$11:$C$610,$H17,'3_Ventas_Diarias'!$A$11:$A$610,">="&'4_Dashboard_DAMABIS'!$P$5,'3_Ventas_Diarias'!$A$11:$A$610,"<="&'4_Dashboard_DAMABIS'!$P$6)) | L17: =IF($H17="","",SUMIFS('3_Ventas_Diarias'!$J$11:$J$610,'3_Ventas_Diarias'!$C$11:$C$610,$H17,'3_Ventas_Diarias'!$A$11:$A$610,">="&'4_Dashboard_DAMABIS'!$P$5,'3_Ventas_Diarias'!$A$11:$A$610,"<="&'4_Dashboard_DAMABIS'!$P$6)) | M17: =IF($H17="","",N($K17)+ROW()/1000000)
H18: =IF('2_Control_de_Stock'!$A$25="","",'2_Control_de_Stock'!$A$25) | I18: =IF('2_Control_de_Stock'!$A$25="","",'2_Control_de_Stock'!$B$25) | J18: =IF($H18="","",SUMIFS('3_Ventas_Diarias'!$E$11:$E$610,'3_Ventas_Diarias'!$C$11:$C$610,$H18,'3_Ventas_Diarias'!$A$11:$A$610,">="&'4_Dashboard_DAMABIS'!$P$5,'3_Ventas_Diarias'!$A$11:$A$610,"<="&'4_Dashboard_DAMABIS'!$P$6)) | K18: =IF($H18="","",SUMIFS('3_Ventas_Diarias'!$G$11:$G$610,'3_Ventas_Diarias'!$C$11:$C$610,$H18,'3_Ventas_Diarias'!$A$11:$A$610,">="&'4_Dashboard_DAMABIS'!$P$5,'3_Ventas_Diarias'!$A$11:$A$610,"<="&'4_Dashboard_DAMABIS'!$P$6)) | L18: =IF($H18="","",SUMIFS('3_Ventas_Diarias'!$J$11:$J$610,'3_Ventas_Diarias'!$C$11:$C$610,$H18,'3_Ventas_Diarias'!$A$11:$A$610,">="&'4_Dashboard_DAMABIS'!$P$5,'3_Ventas_Diarias'!$A$11:$A$610,"<="&'4_Dashboard_DAMABIS'!$P$6)) | M18: =IF($H18="","",N($K18)+ROW()/1000000)
H19: =IF('2_Control_de_Stock'!$A$26="","",'2_Control_de_Stock'!$A$26) | I19: =IF('2_Control_de_Stock'!$A$26="","",'2_Control_de_Stock'!$B$26) | J19: =IF($H19="","",SUMIFS('3_Ventas_Diarias'!$E$11:$E$610,'3_Ventas_Diarias'!$C$11:$C$610,$H19,'3_Ventas_Diarias'!$A$11:$A$610,">="&'4_Dashboard_DAMABIS'!$P$5,'3_Ventas_Diarias'!$A$11:$A$610,"<="&'4_Dashboard_DAMABIS'!$P$6)) | K19: =IF($H19="","",SUMIFS('3_Ventas_Diarias'!$G$11:$G$610,'3_Ventas_Diarias'!$C$11:$C$610,$H19,'3_Ventas_Diarias'!$A$11:$A$610,">="&'4_Dashboard_DAMABIS'!$P$5,'3_Ventas_Diarias'!$A$11:$A$610,"<="&'4_Dashboard_DAMABIS'!$P$6)) | L19: =IF($H19="","",SUMIFS('3_Ventas_Diarias'!$J$11:$J$610,'3_Ventas_Diarias'!$C$11:$C$610,$H19,'3_Ventas_Diarias'!$A$11:$A$610,">="&'4_Dashboard_DAMABIS'!$P$5,'3_Ventas_Diarias'!$A$11:$A$610,"<="&'4_Dashboard_DAMABIS'!$P$6)) | M19: =IF($H19="","",N($K19)+ROW()/1000000)
H20: =IF('2_Control_de_Stock'!$A$27="","",'2_Control_de_Stock'!$A$27) | I20: =IF('2_Control_de_Stock'!$A$27="","",'2_Control_de_Stock'!$B$27) | J20: =IF($H20="","",SUMIFS('3_Ventas_Diarias'!$E$11:$E$610,'3_Ventas_Diarias'!$C$11:$C$610,$H20,'3_Ventas_Diarias'!$A$11:$A$610,">="&'4_Dashboard_DAMABIS'!$P$5,'3_Ventas_Diarias'!$A$11:$A$610,"<="&'4_Dashboard_DAMABIS'!$P$6)) | K20: =IF($H20="","",SUMIFS('3_Ventas_Diarias'!$G$11:$G$610,'3_Ventas_Diarias'!$C$11:$C$610,$H20,'3_Ventas_Diarias'!$A$11:$A$610,">="&'4_Dashboard_DAMABIS'!$P$5,'3_Ventas_Diarias'!$A$11:$A$610,"<="&'4_Dashboard_DAMABIS'!$P$6)) | L20: =IF($H20="","",SUMIFS('3_Ventas_Diarias'!$J$11:$J$610,'3_Ventas_Diarias'!$C$11:$C$610,$H20,'3_Ventas_Diarias'!$A$11:$A$610,">="&'4_Dashboard_DAMABIS'!$P$5,'3_Ventas_Diarias'!$A$11:$A$610,"<="&'4_Dashboard_DAMABIS'!$P$6)) | M20: =IF($H20="","",N($K20)+ROW()/1000000)
H21: =IF('2_Control_de_Stock'!$A$28="","",'2_Control_de_Stock'!$A$28) | I21: =IF('2_Control_de_Stock'!$A$28="","",'2_Control_de_Stock'!$B$28) | J21: =IF($H21="","",SUMIFS('3_Ventas_Diarias'!$E$11:$E$610,'3_Ventas_Diarias'!$C$11:$C$610,$H21,'3_Ventas_Diarias'!$A$11:$A$610,">="&'4_Dashboard_DAMABIS'!$P$5,'3_Ventas_Diarias'!$A$11:$A$610,"<="&'4_Dashboard_DAMABIS'!$P$6)) | K21: =IF($H21="","",SUMIFS('3_Ventas_Diarias'!$G$11:$G$610,'3_Ventas_Diarias'!$C$11:$C$610,$H21,'3_Ventas_Diarias'!$A$11:$A$610,">="&'4_Dashboard_DAMABIS'!$P$5,'3_Ventas_Diarias'!$A$11:$A$610,"<="&'4_Dashboard_DAMABIS'!$P$6)) | L21: =IF($H21="","",SUMIFS('3_Ventas_Diarias'!$J$11:$J$610,'3_Ventas_Diarias'!$C$11:$C$610,$H21,'3_Ventas_Diarias'!$A$11:$A$610,">="&'4_Dashboard_DAMABIS'!$P$5,'3_Ventas_Diarias'!$A$11:$A$610,"<="&'4_Dashboard_DAMABIS'!$P$6)) | M21: =IF($H21="","",N($K21)+ROW()/1000000)
H22: =IF('2_Control_de_Stock'!$A$29="","",'2_Control_de_Stock'!$A$29) | I22: =IF('2_Control_de_Stock'!$A$29="","",'2_Control_de_Stock'!$B$29) | J22: =IF($H22="","",SUMIFS('3_Ventas_Diarias'!$E$11:$E$610,'3_Ventas_Diarias'!$C$11:$C$610,$H22,'3_Ventas_Diarias'!$A$11:$A$610,">="&'4_Dashboard_DAMABIS'!$P$5,'3_Ventas_Diarias'!$A$11:$A$610,"<="&'4_Dashboard_DAMABIS'!$P$6)) | K22: =IF($H22="","",SUMIFS('3_Ventas_Diarias'!$G$11:$G$610,'3_Ventas_Diarias'!$C$11:$C$610,$H22,'3_Ventas_Diarias'!$A$11:$A$610,">="&'4_Dashboard_DAMABIS'!$P$5,'3_Ventas_Diarias'!$A$11:$A$610,"<="&'4_Dashboard_DAMABIS'!$P$6)) | L22: =IF($H22="","",SUMIFS('3_Ventas_Diarias'!$J$11:$J$610,'3_Ventas_Diarias'!$C$11:$C$610,$H22,'3_Ventas_Diarias'!$A$11:$A$610,">="&'4_Dashboard_DAMABIS'!$P$5,'3_Ventas_Diarias'!$A$11:$A$610,"<="&'4_Dashboard_DAMABIS'!$P$6)) | M22: =IF($H22="","",N($K22)+ROW()/1000000)
H23: =IF('2_Control_de_Stock'!$A$30="","",'2_Control_de_Stock'!$A$30) | I23: =IF('2_Control_de_Stock'!$A$30="","",'2_Control_de_Stock'!$B$30) | J23: =IF($H23="","",SUMIFS('3_Ventas_Diarias'!$E$11:$E$610,'3_Ventas_Diarias'!$C$11:$C$610,$H23,'3_Ventas_Diarias'!$A$11:$A$610,">="&'4_Dashboard_DAMABIS'!$P$5,'3_Ventas_Diarias'!$A$11:$A$610,"<="&'4_Dashboard_DAMABIS'!$P$6)) | K23: =IF($H23="","",SUMIFS('3_Ventas_Diarias'!$G$11:$G$610,'3_Ventas_Diarias'!$C$11:$C$610,$H23,'3_Ventas_Diarias'!$A$11:$A$610,">="&'4_Dashboard_DAMABIS'!$P$5,'3_Ventas_Diarias'!$A$11:$A$610,"<="&'4_Dashboard_DAMABIS'!$P$6)) | L23: =IF($H23="","",SUMIFS('3_Ventas_Diarias'!$J$11:$J$610,'3_Ventas_Diarias'!$C$11:$C$610,$H23,'3_Ventas_Diarias'!$A$11:$A$610,">="&'4_Dashboard_DAMABIS'!$P$5,'3_Ventas_Diarias'!$A$11:$A$610,"<="&'4_Dashboard_DAMABIS'!$P$6)) | M23: =IF($H23="","",N($K23)+ROW()/1000000)
H24: =IF('2_Control_de_Stock'!$A$31="","",'2_Control_de_Stock'!$A$31) | I24: =IF('2_Control_de_Stock'!$A$31="","",'2_Control_de_Stock'!$B$31) | J24: =IF($H24="","",SUMIFS('3_Ventas_Diarias'!$E$11:$E$610,'3_Ventas_Diarias'!$C$11:$C$610,$H24,'3_Ventas_Diarias'!$A$11:$A$610,">="&'4_Dashboard_DAMABIS'!$P$5,'3_Ventas_Diarias'!$A$11:$A$610,"<="&'4_Dashboard_DAMABIS'!$P$6)) | K24: =IF($H24="","",SUMIFS('3_Ventas_Diarias'!$G$11:$G$610,'3_Ventas_Diarias'!$C$11:$C$610,$H24,'3_Ventas_Diarias'!$A$11:$A$610,">="&'4_Dashboard_DAMABIS'!$P$5,'3_Ventas_Diarias'!$A$11:$A$610,"<="&'4_Dashboard_DAMABIS'!$P$6)) | L24: =IF($H24="","",SUMIFS('3_Ventas_Diarias'!$J$11:$J$610,'3_Ventas_Diarias'!$C$11:$C$610,$H24,'3_Ventas_Diarias'!$A$11:$A$610,">="&'4_Dashboard_DAMABIS'!$P$5,'3_Ventas_Diarias'!$A$11:$A$610,"<="&'4_Dashboard_DAMABIS'!$P$6)) | M24: =IF($H24="","",N($K24)+ROW()/1000000)
H25: =IF('2_Control_de_Stock'!$A$32="","",'2_Control_de_Stock'!$A$32) | I25: =IF('2_Control_de_Stock'!$A$32="","",'2_Control_de_Stock'!$B$32) | J25: =IF($H25="","",SUMIFS('3_Ventas_Diarias'!$E$11:$E$610,'3_Ventas_Diarias'!$C$11:$C$610,$H25,'3_Ventas_Diarias'!$A$11:$A$610,">="&'4_Dashboard_DAMABIS'!$P$5,'3_Ventas_Diarias'!$A$11:$A$610,"<="&'4_Dashboard_DAMABIS'!$P$6)) | K25: =IF($H25="","",SUMIFS('3_Ventas_Diarias'!$G$11:$G$610,'3_Ventas_Diarias'!$C$11:$C$610,$H25,'3_Ventas_Diarias'!$A$11:$A$610,">="&'4_Dashboard_DAMABIS'!$P$5,'3_Ventas_Diarias'!$A$11:$A$610,"<="&'4_Dashboard_DAMABIS'!$P$6)) | L25: =IF($H25="","",SUMIFS('3_Ventas_Diarias'!$J$11:$J$610,'3_Ventas_Diarias'!$C$11:$C$610,$H25,'3_Ventas_Diarias'!$A$11:$A$610,">="&'4_Dashboard_DAMABIS'!$P$5,'3_Ventas_Diarias'!$A$11:$A$610,"<="&'4_Dashboard_DAMABIS'!$P$6)) | M25: =IF($H25="","",N($K25)+ROW()/1000000)
H26: =IF('2_Control_de_Stock'!$A$33="","",'2_Control_de_Stock'!$A$33) | I26: =IF('2_Control_de_Stock'!$A$33="","",'2_Control_de_Stock'!$B$33) | J26: =IF($H26="","",SUMIFS('3_Ventas_Diarias'!$E$11:$E$610,'3_Ventas_Diarias'!$C$11:$C$610,$H26,'3_Ventas_Diarias'!$A$11:$A$610,">="&'4_Dashboard_DAMABIS'!$P$5,'3_Ventas_Diarias'!$A$11:$A$610,"<="&'4_Dashboard_DAMABIS'!$P$6)) | K26: =IF($H26="","",SUMIFS('3_Ventas_Diarias'!$G$11:$G$610,'3_Ventas_Diarias'!$C$11:$C$610,$H26,'3_Ventas_Diarias'!$A$11:$A$610,">="&'4_Dashboard_DAMABIS'!$P$5,'3_Ventas_Diarias'!$A$11:$A$610,"<="&'4_Dashboard_DAMABIS'!$P$6)) | L26: =IF($H26="","",SUMIFS('3_Ventas_Diarias'!$J$11:$J$610,'3_Ventas_Diarias'!$C$11:$C$610,$H26,'3_Ventas_Diarias'!$A$11:$A$610,">="&'4_Dashboard_DAMABIS'!$P$5,'3_Ventas_Diarias'!$A$11:$A$610,"<="&'4_Dashboard_DAMABIS'!$P$6)) | M26: =IF($H26="","",N($K26)+ROW()/1000000)
H27: =IF('2_Control_de_Stock'!$A$34="","",'2_Control_de_Stock'!$A$34) | I27: =IF('2_Control_de_Stock'!$A$34="","",'2_Control_de_Stock'!$B$34) | J27: =IF($H27="","",SUMIFS('3_Ventas_Diarias'!$E$11:$E$610,'3_Ventas_Diarias'!$C$11:$C$610,$H27,'3_Ventas_Diarias'!$A$11:$A$610,">="&'4_Dashboard_DAMABIS'!$P$5,'3_Ventas_Diarias'!$A$11:$A$610,"<="&'4_Dashboard_DAMABIS'!$P$6)) | K27: =IF($H27="","",SUMIFS('3_Ventas_Diarias'!$G$11:$G$610,'3_Ventas_Diarias'!$C$11:$C$610,$H27,'3_Ventas_Diarias'!$A$11:$A$610,">="&'4_Dashboard_DAMABIS'!$P$5,'3_Ventas_Diarias'!$A$11:$A$610,"<="&'4_Dashboard_DAMABIS'!$P$6)) | L27: =IF($H27="","",SUMIFS('3_Ventas_Diarias'!$J$11:$J$610,'3_Ventas_Diarias'!$C$11:$C$610,$H27,'3_Ventas_Diarias'!$A$11:$A$610,">="&'4_Dashboard_DAMABIS'!$P$5,'3_Ventas_Diarias'!$A$11:$A$610,"<="&'4_Dashboard_DAMABIS'!$P$6)) | M27: =IF($H27="","",N($K27)+ROW()/1000000)
H28: =IF('2_Control_de_Stock'!$A$35="","",'2_Control_de_Stock'!$A$35) | I28: =IF('2_Control_de_Stock'!$A$35="","",'2_Control_de_Stock'!$B$35) | J28: =IF($H28="","",SUMIFS('3_Ventas_Diarias'!$E$11:$E$610,'3_Ventas_Diarias'!$C$11:$C$610,$H28,'3_Ventas_Diarias'!$A$11:$A$610,">="&'4_Dashboard_DAMABIS'!$P$5,'3_Ventas_Diarias'!$A$11:$A$610,"<="&'4_Dashboard_DAMABIS'!$P$6)) | K28: =IF($H28="","",SUMIFS('3_Ventas_Diarias'!$G$11:$G$610,'3_Ventas_Diarias'!$C$11:$C$610,$H28,'3_Ventas_Diarias'!$A$11:$A$610,">="&'4_Dashboard_DAMABIS'!$P$5,'3_Ventas_Diarias'!$A$11:$A$610,"<="&'4_Dashboard_DAMABIS'!$P$6)) | L28: =IF($H28="","",SUMIFS('3_Ventas_Diarias'!$J$11:$J$610,'3_Ventas_Diarias'!$C$11:$C$610,$H28,'3_Ventas_Diarias'!$A$11:$A$610,">="&'4_Dashboard_DAMABIS'!$P$5,'3_Ventas_Diarias'!$A$11:$A$610,"<="&'4_Dashboard_DAMABIS'!$P$6)) | M28: =IF($H28="","",N($K28)+ROW()/1000000)
H29: =IF('2_Control_de_Stock'!$A$36="","",'2_Control_de_Stock'!$A$36) | I29: =IF('2_Control_de_Stock'!$A$36="","",'2_Control_de_Stock'!$B$36) | J29: =IF($H29="","",SUMIFS('3_Ventas_Diarias'!$E$11:$E$610,'3_Ventas_Diarias'!$C$11:$C$610,$H29,'3_Ventas_Diarias'!$A$11:$A$610,">="&'4_Dashboard_DAMABIS'!$P$5,'3_Ventas_Diarias'!$A$11:$A$610,"<="&'4_Dashboard_DAMABIS'!$P$6)) | K29: =IF($H29="","",SUMIFS('3_Ventas_Diarias'!$G$11:$G$610,'3_Ventas_Diarias'!$C$11:$C$610,$H29,'3_Ventas_Diarias'!$A$11:$A$610,">="&'4_Dashboard_DAMABIS'!$P$5,'3_Ventas_Diarias'!$A$11:$A$610,"<="&'4_Dashboard_DAMABIS'!$P$6)) | L29: =IF($H29="","",SUMIFS('3_Ventas_Diarias'!$J$11:$J$610,'3_Ventas_Diarias'!$C$11:$C$610,$H29,'3_Ventas_Diarias'!$A$11:$A$610,">="&'4_Dashboard_DAMABIS'!$P$5,'3_Ventas_Diarias'!$A$11:$A$610,"<="&'4_Dashboard_DAMABIS'!$P$6)) | M29: =IF($H29="","",N($K29)+ROW()/1000000)
H30: =IF('2_Control_de_Stock'!$A$37="","",'2_Control_de_Stock'!$A$37) | I30: =IF('2_Control_de_Stock'!$A$37="","",'2_Control_de_Stock'!$B$37) | J30: =IF($H30="","",SUMIFS('3_Ventas_Diarias'!$E$11:$E$610,'3_Ventas_Diarias'!$C$11:$C$610,$H30,'3_Ventas_Diarias'!$A$11:$A$610,">="&'4_Dashboard_DAMABIS'!$P$5,'3_Ventas_Diarias'!$A$11:$A$610,"<="&'4_Dashboard_DAMABIS'!$P$6)) | K30: =IF($H30="","",SUMIFS('3_Ventas_Diarias'!$G$11:$G$610,'3_Ventas_Diarias'!$C$11:$C$610,$H30,'3_Ventas_Diarias'!$A$11:$A$610,">="&'4_Dashboard_DAMABIS'!$P$5,'3_Ventas_Diarias'!$A$11:$A$610,"<="&'4_Dashboard_DAMABIS'!$P$6)) | L30: =IF($H30="","",SUMIFS('3_Ventas_Diarias'!$J$11:$J$610,'3_Ventas_Diarias'!$C$11:$C$610,$H30,'3_Ventas_Diarias'!$A$11:$A$610,">="&'4_Dashboard_DAMABIS'!$P$5,'3_Ventas_Diarias'!$A$11:$A$610,"<="&'4_Dashboard_DAMABIS'!$P$6)) | M30: =IF($H30="","",N($K30)+ROW()/1000000)
H31: =IF('2_Control_de_Stock'!$A$38="","",'2_Control_de_Stock'!$A$38) | I31: =IF('2_Control_de_Stock'!$A$38="","",'2_Control_de_Stock'!$B$38) | J31: =IF($H31="","",SUMIFS('3_Ventas_Diarias'!$E$11:$E$610,'3_Ventas_Diarias'!$C$11:$C$610,$H31,'3_Ventas_Diarias'!$A$11:$A$610,">="&'4_Dashboard_DAMABIS'!$P$5,'3_Ventas_Diarias'!$A$11:$A$610,"<="&'4_Dashboard_DAMABIS'!$P$6)) | K31: =IF($H31="","",SUMIFS('3_Ventas_Diarias'!$G$11:$G$610,'3_Ventas_Diarias'!$C$11:$C$610,$H31,'3_Ventas_Diarias'!$A$11:$A$610,">="&'4_Dashboard_DAMABIS'!$P$5,'3_Ventas_Diarias'!$A$11:$A$610,"<="&'4_Dashboard_DAMABIS'!$P$6)) | L31: =IF($H31="","",SUMIFS('3_Ventas_Diarias'!$J$11:$J$610,'3_Ventas_Diarias'!$C$11:$C$610,$H31,'3_Ventas_Diarias'!$A$11:$A$610,">="&'4_Dashboard_DAMABIS'!$P$5,'3_Ventas_Diarias'!$A$11:$A$610,"<="&'4_Dashboard_DAMABIS'!$P$6)) | M31: =IF($H31="","",N($K31)+ROW()/1000000)
H32: =IF('2_Control_de_Stock'!$A$39="","",'2_Control_de_Stock'!$A$39) | I32: =IF('2_Control_de_Stock'!$A$39="","",'2_Control_de_Stock'!$B$39) | J32: =IF($H32="","",SUMIFS('3_Ventas_Diarias'!$E$11:$E$610,'3_Ventas_Diarias'!$C$11:$C$610,$H32,'3_Ventas_Diarias'!$A$11:$A$610,">="&'4_Dashboard_DAMABIS'!$P$5,'3_Ventas_Diarias'!$A$11:$A$610,"<="&'4_Dashboard_DAMABIS'!$P$6)) | K32: =IF($H32="","",SUMIFS('3_Ventas_Diarias'!$G$11:$G$610,'3_Ventas_Diarias'!$C$11:$C$610,$H32,'3_Ventas_Diarias'!$A$11:$A$610,">="&'4_Dashboard_DAMABIS'!$P$5,'3_Ventas_Diarias'!$A$11:$A$610,"<="&'4_Dashboard_DAMABIS'!$P$6)) | L32: =IF($H32="","",SUMIFS('3_Ventas_Diarias'!$J$11:$J$610,'3_Ventas_Diarias'!$C$11:$C$610,$H32,'3_Ventas_Diarias'!$A$11:$A$610,">="&'4_Dashboard_DAMABIS'!$P$5,'3_Ventas_Diarias'!$A$11:$A$610,"<="&'4_Dashboard_DAMABIS'!$P$6)) | M32: =IF($H32="","",N($K32)+ROW()/1000000)
H33: =IF('2_Control_de_Stock'!$A$40="","",'2_Control_de_Stock'!$A$40) | I33: =IF('2_Control_de_Stock'!$A$40="","",'2_Control_de_Stock'!$B$40) | J33: =IF($H33="","",SUMIFS('3_Ventas_Diarias'!$E$11:$E$610,'3_Ventas_Diarias'!$C$11:$C$610,$H33,'3_Ventas_Diarias'!$A$11:$A$610,">="&'4_Dashboard_DAMABIS'!$P$5,'3_Ventas_Diarias'!$A$11:$A$610,"<="&'4_Dashboard_DAMABIS'!$P$6)) | K33: =IF($H33="","",SUMIFS('3_Ventas_Diarias'!$G$11:$G$610,'3_Ventas_Diarias'!$C$11:$C$610,$H33,'3_Ventas_Diarias'!$A$11:$A$610,">="&'4_Dashboard_DAMABIS'!$P$5,'3_Ventas_Diarias'!$A$11:$A$610,"<="&'4_Dashboard_DAMABIS'!$P$6)) | L33: =IF($H33="","",SUMIFS('3_Ventas_Diarias'!$J$11:$J$610,'3_Ventas_Diarias'!$C$11:$C$610,$H33,'3_Ventas_Diarias'!$A$11:$A$610,">="&'4_Dashboard_DAMABIS'!$P$5,'3_Ventas_Diarias'!$A$11:$A$610,"<="&'4_Dashboard_DAMABIS'!$P$6)) | M33: =IF($H33="","",N($K33)+ROW()/1000000)
H34: =IF('2_Control_de_Stock'!$A$41="","",'2_Control_de_Stock'!$A$41) | I34: =IF('2_Control_de_Stock'!$A$41="","",'2_Control_de_Stock'!$B$41) | J34: =IF($H34="","",SUMIFS('3_Ventas_Diarias'!$E$11:$E$610,'3_Ventas_Diarias'!$C$11:$C$610,$H34,'3_Ventas_Diarias'!$A$11:$A$610,">="&'4_Dashboard_DAMABIS'!$P$5,'3_Ventas_Diarias'!$A$11:$A$610,"<="&'4_Dashboard_DAMABIS'!$P$6)) | K34: =IF($H34="","",SUMIFS('3_Ventas_Diarias'!$G$11:$G$610,'3_Ventas_Diarias'!$C$11:$C$610,$H34,'3_Ventas_Diarias'!$A$11:$A$610,">="&'4_Dashboard_DAMABIS'!$P$5,'3_Ventas_Diarias'!$A$11:$A$610,"<="&'4_Dashboard_DAMABIS'!$P$6)) | L34: =IF($H34="","",SUMIFS('3_Ventas_Diarias'!$J$11:$J$610,'3_Ventas_Diarias'!$C$11:$C$610,$H34,'3_Ventas_Diarias'!$A$11:$A$610,">="&'4_Dashboard_DAMABIS'!$P$5,'3_Ventas_Diarias'!$A$11:$A$610,"<="&'4_Dashboard_DAMABIS'!$P$6)) | M34: =IF($H34="","",N($K34)+ROW()/1000000)
H35: =IF('2_Control_de_Stock'!$A$42="","",'2_Control_de_Stock'!$A$42) | I35: =IF('2_Control_de_Stock'!$A$42="","",'2_Control_de_Stock'!$B$42) | J35: =IF($H35="","",SUMIFS('3_Ventas_Diarias'!$E$11:$E$610,'3_Ventas_Diarias'!$C$11:$C$610,$H35,'3_Ventas_Diarias'!$A$11:$A$610,">="&'4_Dashboard_DAMABIS'!$P$5,'3_Ventas_Diarias'!$A$11:$A$610,"<="&'4_Dashboard_DAMABIS'!$P$6)) | K35: =IF($H35="","",SUMIFS('3_Ventas_Diarias'!$G$11:$G$610,'3_Ventas_Diarias'!$C$11:$C$610,$H35,'3_Ventas_Diarias'!$A$11:$A$610,">="&'4_Dashboard_DAMABIS'!$P$5,'3_Ventas_Diarias'!$A$11:$A$610,"<="&'4_Dashboard_DAMABIS'!$P$6)) | L35: =IF($H35="","",SUMIFS('3_Ventas_Diarias'!$J$11:$J$610,'3_Ventas_Diarias'!$C$11:$C$610,$H35,'3_Ventas_Diarias'!$A$11:$A$610,">="&'4_Dashboard_DAMABIS'!$P$5,'3_Ventas_Diarias'!$A$11:$A$610,"<="&'4_Dashboard_DAMABIS'!$P$6)) | M35: =IF($H35="","",N($K35)+ROW()/1000000)
H36: =IF('2_Control_de_Stock'!$A$43="","",'2_Control_de_Stock'!$A$43) | I36: =IF('2_Control_de_Stock'!$A$43="","",'2_Control_de_Stock'!$B$43) | J36: =IF($H36="","",SUMIFS('3_Ventas_Diarias'!$E$11:$E$610,'3_Ventas_Diarias'!$C$11:$C$610,$H36,'3_Ventas_Diarias'!$A$11:$A$610,">="&'4_Dashboard_DAMABIS'!$P$5,'3_Ventas_Diarias'!$A$11:$A$610,"<="&'4_Dashboard_DAMABIS'!$P$6)) | K36: =IF($H36="","",SUMIFS('3_Ventas_Diarias'!$G$11:$G$610,'3_Ventas_Diarias'!$C$11:$C$610,$H36,'3_Ventas_Diarias'!$A$11:$A$610,">="&'4_Dashboard_DAMABIS'!$P$5,'3_Ventas_Diarias'!$A$11:$A$610,"<="&'4_Dashboard_DAMABIS'!$P$6)) | L36: =IF($H36="","",SUMIFS('3_Ventas_Diarias'!$J$11:$J$610,'3_Ventas_Diarias'!$C$11:$C$610,$H36,'3_Ventas_Diarias'!$A$11:$A$610,">="&'4_Dashboard_DAMABIS'!$P$5,'3_Ventas_Diarias'!$A$11:$A$610,"<="&'4_Dashboard_DAMABIS'!$P$6)) | M36: =IF($H36="","",N($K36)+ROW()/1000000)
H37: =IF('2_Control_de_Stock'!$A$44="","",'2_Control_de_Stock'!$A$44) | I37: =IF('2_Control_de_Stock'!$A$44="","",'2_Control_de_Stock'!$B$44) | J37: =IF($H37="","",SUMIFS('3_Ventas_Diarias'!$E$11:$E$610,'3_Ventas_Diarias'!$C$11:$C$610,$H37,'3_Ventas_Diarias'!$A$11:$A$610,">="&'4_Dashboard_DAMABIS'!$P$5,'3_Ventas_Diarias'!$A$11:$A$610,"<="&'4_Dashboard_DAMABIS'!$P$6)) | K37: =IF($H37="","",SUMIFS('3_Ventas_Diarias'!$G$11:$G$610,'3_Ventas_Diarias'!$C$11:$C$610,$H37,'3_Ventas_Diarias'!$A$11:$A$610,">="&'4_Dashboard_DAMABIS'!$P$5,'3_Ventas_Diarias'!$A$11:$A$610,"<="&'4_Dashboard_DAMABIS'!$P$6)) | L37: =IF($H37="","",SUMIFS('3_Ventas_Diarias'!$J$11:$J$610,'3_Ventas_Diarias'!$C$11:$C$610,$H37,'3_Ventas_Diarias'!$A$11:$A$610,">="&'4_Dashboard_DAMABIS'!$P$5,'3_Ventas_Diarias'!$A$11:$A$610,"<="&'4_Dashboard_DAMABIS'!$P$6)) | M37: =IF($H37="","",N($K37)+ROW()/1000000)
H38: =IF('2_Control_de_Stock'!$A$45="","",'2_Control_de_Stock'!$A$45) | I38: =IF('2_Control_de_Stock'!$A$45="","",'2_Control_de_Stock'!$B$45) | J38: =IF($H38="","",SUMIFS('3_Ventas_Diarias'!$E$11:$E$610,'3_Ventas_Diarias'!$C$11:$C$610,$H38,'3_Ventas_Diarias'!$A$11:$A$610,">="&'4_Dashboard_DAMABIS'!$P$5,'3_Ventas_Diarias'!$A$11:$A$610,"<="&'4_Dashboard_DAMABIS'!$P$6)) | K38: =IF($H38="","",SUMIFS('3_Ventas_Diarias'!$G$11:$G$610,'3_Ventas_Diarias'!$C$11:$C$610,$H38,'3_Ventas_Diarias'!$A$11:$A$610,">="&'4_Dashboard_DAMABIS'!$P$5,'3_Ventas_Diarias'!$A$11:$A$610,"<="&'4_Dashboard_DAMABIS'!$P$6)) | L38: =IF($H38="","",SUMIFS('3_Ventas_Diarias'!$J$11:$J$610,'3_Ventas_Diarias'!$C$11:$C$610,$H38,'3_Ventas_Diarias'!$A$11:$A$610,">="&'4_Dashboard_DAMABIS'!$P$5,'3_Ventas_Diarias'!$A$11:$A$610,"<="&'4_Dashboard_DAMABIS'!$P$6)) | M38: =IF($H38="","",N($K38)+ROW()/1000000)
H39: =IF('2_Control_de_Stock'!$A$46="","",'2_Control_de_Stock'!$A$46) | I39: =IF('2_Control_de_Stock'!$A$46="","",'2_Control_de_Stock'!$B$46) | J39: =IF($H39="","",SUMIFS('3_Ventas_Diarias'!$E$11:$E$610,'3_Ventas_Diarias'!$C$11:$C$610,$H39,'3_Ventas_Diarias'!$A$11:$A$610,">="&'4_Dashboard_DAMABIS'!$P$5,'3_Ventas_Diarias'!$A$11:$A$610,"<="&'4_Dashboard_DAMABIS'!$P$6)) | K39: =IF($H39="","",SUMIFS('3_Ventas_Diarias'!$G$11:$G$610,'3_Ventas_Diarias'!$C$11:$C$610,$H39,'3_Ventas_Diarias'!$A$11:$A$610,">="&'4_Dashboard_DAMABIS'!$P$5,'3_Ventas_Diarias'!$A$11:$A$610,"<="&'4_Dashboard_DAMABIS'!$P$6)) | L39: =IF($H39="","",SUMIFS('3_Ventas_Diarias'!$J$11:$J$610,'3_Ventas_Diarias'!$C$11:$C$610,$H39,'3_Ventas_Diarias'!$A$11:$A$610,">="&'4_Dashboard_DAMABIS'!$P$5,'3_Ventas_Diarias'!$A$11:$A$610,"<="&'4_Dashboard_DAMABIS'!$P$6)) | M39: =IF($H39="","",N($K39)+ROW()/1000000)
H40: =IF('2_Control_de_Stock'!$A$47="","",'2_Control_de_Stock'!$A$47) | I40: =IF('2_Control_de_Stock'!$A$47="","",'2_Control_de_Stock'!$B$47) | J40: =IF($H40="","",SUMIFS('3_Ventas_Diarias'!$E$11:$E$610,'3_Ventas_Diarias'!$C$11:$C$610,$H40,'3_Ventas_Diarias'!$A$11:$A$610,">="&'4_Dashboard_DAMABIS'!$P$5,'3_Ventas_Diarias'!$A$11:$A$610,"<="&'4_Dashboard_DAMABIS'!$P$6)) | K40: =IF($H40="","",SUMIFS('3_Ventas_Diarias'!$G$11:$G$610,'3_Ventas_Diarias'!$C$11:$C$610,$H40,'3_Ventas_Diarias'!$A$11:$A$610,">="&'4_Dashboard_DAMABIS'!$P$5,'3_Ventas_Diarias'!$A$11:$A$610,"<="&'4_Dashboard_DAMABIS'!$P$6)) | L40: =IF($H40="","",SUMIFS('3_Ventas_Diarias'!$J$11:$J$610,'3_Ventas_Diarias'!$C$11:$C$610,$H40,'3_Ventas_Diarias'!$A$11:$A$610,">="&'4_Dashboard_DAMABIS'!$P$5,'3_Ventas_Diarias'!$A$11:$A$610,"<="&'4_Dashboard_DAMABIS'!$P$6)) | M40: =IF($H40="","",N($K40)+ROW()/1000000)
H41: =IF('2_Control_de_Stock'!$A$48="","",'2_Control_de_Stock'!$A$48) | I41: =IF('2_Control_de_Stock'!$A$48="","",'2_Control_de_Stock'!$B$48) | J41: =IF($H41="","",SUMIFS('3_Ventas_Diarias'!$E$11:$E$610,'3_Ventas_Diarias'!$C$11:$C$610,$H41,'3_Ventas_Diarias'!$A$11:$A$610,">="&'4_Dashboard_DAMABIS'!$P$5,'3_Ventas_Diarias'!$A$11:$A$610,"<="&'4_Dashboard_DAMABIS'!$P$6)) | K41: =IF($H41="","",SUMIFS('3_Ventas_Diarias'!$G$11:$G$610,'3_Ventas_Diarias'!$C$11:$C$610,$H41,'3_Ventas_Diarias'!$A$11:$A$610,">="&'4_Dashboard_DAMABIS'!$P$5,'3_Ventas_Diarias'!$A$11:$A$610,"<="&'4_Dashboard_DAMABIS'!$P$6)) | L41: =IF($H41="","",SUMIFS('3_Ventas_Diarias'!$J$11:$J$610,'3_Ventas_Diarias'!$C$11:$C$610,$H41,'3_Ventas_Diarias'!$A$11:$A$610,">="&'4_Dashboard_DAMABIS'!$P$5,'3_Ventas_Diarias'!$A$11:$A$610,"<="&'4_Dashboard_DAMABIS'!$P$6)) | M41: =IF($H41="","",N($K41)+ROW()/1000000)
...

Sheet 1_Compras_e_Inventario_Inicial
A1: DAMABIS · Compras e Inventario Inicial Registro de mercancía ingresada · Librería y Útiles Escolares
A6: 💰 GASTO TOTAL EN COMPRAS | C6: 📦 UNIDADES INGRESADAS | E6: 🧾 N° DE TRANSACCIONES | G6: 🏭 PROVEEDORES | H6: 📊 COSTO UNIT. PROMEDIO
A7: =SUM(I11:I510) | C7: =SUM(G11:G510) | E7: =SUMPRODUCT((B11:B510<>"")/COUNTIF(B11:B510,B11:B510&"")) | G7: =SUMPRODUCT((C11:C510<>"")/COUNTIF(C11:C510,C11:C510&"")) | H7: =IFERROR(SUM(I11:I510)/SUM(G11:G510),0)
A9: ✏️ Celdas en AZUL = captura manual. Celdas en NEGRO = fórmula automática (no escribir). Usa las listas desplegables en Proveedor, SKU y Categoría.
A10: Fecha | B10: ID Transacción | C10: Proveedor | D10: Código/SKU | E10: Descripción del Producto | F10: Categoría | G10: Cantidad Comprada | H10: Costo Unitario | I10: Costo Total
A11: 46236 | B11: C-2026-001 | C11: Distribuidora Lima Papel SAC | D11: PAP-001 | E11: Papel Bond A4 75g (millar) | F11: Papelería | G11: 30 | H11: 13.5 | I11: =IF(OR($G11="",$H11=""),"",$G11*$H11)
A12: 46236 | B12: C-2026-001 | C12: Distribuidora Lima Papel SAC | D12: CUA-010 | E12: Cuaderno A4 cuadriculado 100h | F12: Cuadernos | G12: 120 | H12: 4.2 | I12: =IF(OR($G12="",$H12=""),"",$G12*$H12)
A13: 46237 | B13: C-2026-002 | C13: Importadora Kawaii Perú EIRL | D13: KAW-101 | E13: Set stickers ajolote kawaii | F13: Kawaii/Escolar | G13: 200 | H13: 2.1 | I13: =IF(OR($G13="",$H13=""),"",$G13*$H13)
A14: 46237 | B14: C-2026-002 | C14: Importadora Kawaii Perú EIRL | D14: KAW-102 | E14: Lapicero gel pastel x6 | F14: Kawaii/Escolar | G14: 150 | H14: 5.4 | I14: =IF(OR($G14="",$H14=""),"",$G14*$H14)
A15: 46239 | B15: C-2026-003 | C15: Editorial Andina SAC | D15: LIB-201 | E15: Libro infantil ilustrado | F15: Libros | G15: 60 | H15: 18 | I15: =IF(OR($G15="",$H15=""),"",$G15*$H15)
A16: 46239 | B16: C-2026-003 | C16: Editorial Andina SAC | D16: LIB-202 | E16: Diccionario escolar | F16: Libros | G16: 25 | H16: 22 | I16: =IF(OR($G16="",$H16=""),"",$G16*$H16)
A17: 46242 | B17: C-2026-004 | C17: Arte & Color Distribuciones | D17: ART-301 | E17: Témpera 12 colores | F17: Arte | G17: 80 | H17: 7.8 | I17: =IF(OR($G17="",$H17=""),"",$G17*$H17)
A18: 46242 | B18: C-2026-004 | C18: Arte & Color Distribuciones | D18: ART-302 | E18: Block de dibujo A3 | F18: Arte | G18: 90 | H18: 6.3 | I18: =IF(OR($G18="",$H18=""),"",$G18*$H18)
A19: 46244 | B19: C-2026-005 | C19: Faber Perú SA | D19: ESC-401 | E19: Colores x24 largos | F19: Escritura | G19: 100 | H19: 11.5 | I19: =IF(OR($G19="",$H19=""),"",$G19*$H19)
A20: 46244 | B20: C-2026-005 | C20: Faber Perú SA | D20: ESC-402 | E20: Plumón resaltador pastel x4 | F20: Escritura | G20: 140 | H20: 4.9 | I20: =IF(OR($G20="",$H20=""),"",$G20*$H20)
A21: 46246 | B21: C-2026-006 | C21: Mayorista Mesa Redonda | D21: MOC-501 | E21: Mochila escolar estampada | F21: Mochilas y Loncheras | G21: 8 | H21: 32 | I21: =IF(OR($G21="",$H21=""),"",$G21*$H21)
A22: 46246 | B22: C-2026-006 | C22: Mayorista Mesa Redonda | D22: MOC-502 | E22: Lonchera térmica kawaii | F22: Mochilas y Loncheras | G22: 10 | H22: 21 | I22: =IF(OR($G22="",$H22=""),"",$G22*$H22)
... A30: 46266 | B30: C-2026-013 | C30: Distribuidora Lima Papel SAC | D30: CUA-011 | E30: Cuaderno anillado A5 80h | F30: Cuadernos | G30: 130 | H30: 3.9 | I30: =IF(OR($G30="",$H30=""),"",$G30*$H30)
I31: =IF(OR($G31="",$H31=""),"",$G31*$H31)
I32: =IF(OR($G32="",$H32=""),"",$G32*$H32)
I33: =IF(OR($G33="",$H33=""),"",$G33*$H33)
I34: =IF(OR($G34="",$H34=""),"",$G34*$H34)
I35: =IF(OR($G35="",$H35=""),"",$G35*$H35)
I36: =IF(OR($G36="",$H36=""),"",$G36*$H36)
I37: =IF(OR($G37="",$H37=""),"",$G37*$H37)
I38: =IF(OR($G38="",$H38=""),"",$G38*$H38)
I39: =IF(OR($G39="",$H39=""),"",$G39*$H39)
I40: =IF(OR($G40="",$H40=""),"",$G40*$H40)
I41: =IF(OR($G41="",$H41=""),"",$G41*$H41)
I42: =IF(OR($G42="",$H42=""),"",$G42*$H42)
... I510: =IF(OR($G510="",$H510=""),"",$G510*$H510)

Sheet 2_Control_de_Stock
A1: DAMABIS · Control de Stock Maestro de productos · Cálculo automático de existencias y márgenes
A6: 🧮 SKUs ACTIVOS | C6: 🏦 VALOR INVENTARIO (COSTO) | E6: 💵 VALOR INVENTARIO (VENTA) | G6: 📈 MARGEN PROMEDIO | I6: 🔴 SKUs SIN STOCK | K6: 🟠 SKUs POR REPONER | M6: 📦 UNIDADES EN TIENDA
A7: =COUNTIF(A11:A210,"?*") | C7: =SUM(L11:L210) | E7: =SUM(M11:M210) | G7: =IFERROR((SUM(M11:M210)-SUM(L11:L210))/SUM(M11:M210),0) | I7: =COUNTIF(I11:I210,"*SIN STOCK*") | K7: =COUNTIF(I11:I210,"*REPONER*") | M7: =SUM(G11:G210)
A9: ✏️ Captura manual (azul): SKU · Descripción · Categoría · Stock Inicial · Stock Mínimo · Precio de Venta. ⚙️ El resto se calcula solo desde las hojas 1 y 3.
A10: Código/SKU | B10: Descripción | C10: Categoría | D10: Stock Inicial | E10: Entradas Totales | F10: Salidas Totales | G10: Stock Actual | H10: Stock Mínimo | I10: Alerta de Estado | J10: Costo Promedio Unit. | K10: Precio de Venta | L10: Valor Total a Costo | M10: Valor Total a Venta | N10: % Margen Bruto
A11: PAP-001 | B11: Papel Bond A4 75g (millar) | C11: Papelería | D11: 5 | E11: =IF($A11="","",SUMIFS('1_Compras_e_Inventario_Inicial'!$G$11:$G$510,'1_Compras_e_Inventario_Inicial'!$D$11:$D$510,$A11)) | F11: =IF($A11="","",SUMIFS('3_Ventas_Diarias'!$E$11:$E$610,'3_Ventas_Diarias'!$C$11:$C$610,$A11)) | G11: =IF($A11="","",N($D11)+N($E11)-N($F11)) | H11: 4 | I11: =IF($A11="","",IF($G11<=0,"🔴 SIN STOCK",IF($G11<=$H11,"🟠 REPONER",IF($G11<=$H11*1.5,"🟡 VIGILAR","🟢 OK")))) | J11: =IF($A11="","",IFERROR(SUMIFS('1_Compras_e_Inventario_Inicial'!$I$11:$I$510,'1_Compras_e_Inventario_Inicial'!$D$11:$D$510,$A11)/SUMIFS('1_Compras_e_Inventario_Inicial'!$G$11:$G$510,'1_Compras_e_Inventario_Inicial'!$D$11:$D$510,$A11),0)) | K11: 19.9 | L11: =IF($A11="","",$G11*$J11) | M11: =IF($A11="","",$G11*$K11) | N11: =IF($A11="","",IFERROR(($K11-$J11)/$K11,0))
A12: PAP-002 | B12: Cartulina de colores (pliego) | C12: Papelería | D12: 50 | E12: =IF($A12="","",SUMIFS('1_Compras_e_Inventario_Inicial'!$G$11:$G$510,'1_Compras_e_Inventario_Inicial'!$D$11:$D$510,$A12)) | F12: =IF($A12="","",SUMIFS('3_Ventas_Diarias'!$E$11:$E$610,'3_Ventas_Diarias'!$C$11:$C$610,$A12)) | G12: =IF($A12="","",N($D12)+N($E12)-N($F12)) | H12: 60 | I12: =IF($A12="","",IF($G12<=0,"🔴 SIN STOCK",IF($G12<=$H12,"🟠 REPONER",IF($G12<=$H12*1.5,"🟡 VIGILAR","🟢 OK")))) | J12: =IF($A12="","",IFERROR(SUMIFS('1_Compras_e_Inventario_Inicial'!$I$11:$I$510,'1_Compras_e_Inventario_Inicial'!$D$11:$D$510,$A12)/SUMIFS('1_Compras_e_Inventario_Inicial'!$G$11:$G$510,'1_Compras_e_Inventario_Inicial'!$D$11:$D$510,$A12),0)) | K12: 1.5 | L12: =IF($A12="","",$G12*$J12) | M12: =IF($A12="","",$G12*$K12) | N12: =IF($A12="","",IFERROR(($K12-$J12)/$K12,0))
A13: CUA-010 | B13: Cuaderno A4 cuadriculado 100h | C13: Cuadernos | D13: 20 | E13: =IF($A13="","",SUMIFS('1_Compras_e_Inventario_Inicial'!$G$11:$G$510,'1_Compras_e_Inventario_Inicial'!$D$11:$D$510,$A13)) | F13: =IF($A13="","",SUMIFS('3_Ventas_Diarias'!$E$11:$E$610,'3_Ventas_Diarias'!$C$11:$C$610,$A13)) | G13: =IF($A13="","",N($D13)+N($E13)-N($F13)) | H13: 30 | I13: =IF($A13="","",IF($G13<=0,"🔴 SIN STOCK",IF($G13<=$H13,"🟠 REPONER",IF($G13<=$H13*1.5,"🟡 VIGILAR","🟢 OK")))) | J13: =IF($A13="","",IFERROR(SUMIFS('1_Compras_e_Inventario_Inicial'!$I$11:$I$510,'1_Compras_e_Inventario_Inicial'!$D$11:$D$510,$A13)/SUMIFS('1_Compras_e_Inventario_Inicial'!$G$11:$G$510,'1_Compras_e_Inventario_Inicial'!$D$11:$D$510,$A13),0)) | K13: 6.5 | L13: =IF($A13="","",$G13*$J13) | M13: =IF($A13="","",$G13*$K13) | N13: =IF($A13="","",IFERROR(($K13-$J13)/$K13,0))
A14: CUA-011 | B14: Cuaderno anillado A5 80h | C14: Cuadernos | D14: 15 | E14: =IF($A14="","",SUMIFS('1_Compras_e_Inventario_Inicial'!$G$11:$G$510,'1_Compras_e_Inventario_Inicial'!$D$11:$D$510,$A14)) | F14: =IF($A14="","",SUMIFS('3_Ventas_Diarias'!$E$11:$E$610,'3_Ventas_Diarias'!$C$11:$C$610,$A14)) | G14: =IF($A14="","",N($D14)+N($E14)-N($F14)) | H14: 25 | I14: =IF($A14="","",IF($G14<=0,"🔴 SIN STOCK",IF($G14<=$H14,"🟠 REPONER",IF($G14<=$H14*1.5,"🟡 VIGILAR","🟢 OK")))) | J14: =IF($A14="","",IFERROR(SUMIFS('1_Compras_e_Inventario_Inicial'!$I$11:$I$510,'1_Compras_e_Inventario_Inicial'!$D$11:$D$510,$A14)/SUMIFS('1_Compras_e_Inventario_Inicial'!$G$11:$G$510,'1_Compras_e_Inventario_Inicial'!$D$11:$D$510,$A14),0)) | K14: 5.9 | L14: =IF($A14="","",$G14*$J14) | M14: =IF($A14="","",$G14*$K14) | N14: =IF($A14="","",IFERROR(($K14-$J14)/$K14,0))
A15: KAW-101 | B15: Set stickers ajolote kawaii | C15: Kawaii/Escolar | D15: 30 | E15: =IF($A15="","",SUMIFS('1_Compras_e_Inventario_Inicial'!$G$11:$G$510,'1_Compras_e_Inventario_Inicial'!$D$11:$D$510,$A15)) | F15: =IF($A15="","",SUMIFS('3_Ventas_Diarias'!$E$11:$E$610,'3_Ventas_Diarias'!$C$11:$C$610,$A15)) | G15: =IF($A15="","",N($D15)+N($E15)-N($F15)) | H15: 40 | I15: =IF($A15="","",IF($G15<=0,"🔴 SIN STOCK",IF($G15<=$H15,"🟠 REPONER",IF($G15<=$H15*1.5,"🟡 VIGILAR","🟢 OK")))) | J15: =IF($A15="","",IFERROR(SUMIFS('1_Compras_e_Inventario_Inicial'!$I$11:$I$510,'1_Compras_e_Inventario_Inicial'!$D$11:$D$510,$A15)/SUMIFS('1_Compras_e_Inventario_Inicial'!$G$11:$G$510,'1_Compras_e_Inventario_Inicial'!$D$11:$D$510,$A15),0)) | K15: 4.5 | L15: =IF($A15="","",$G15*$J15) | M15: =IF($A15="","",$G15*$K15) | N15: =IF($A15="","",IFERROR(($K15-$J15)/$K15,0))
A16: KAW-102 | B16: Lapicero gel pastel x6 | C16: Kawaii/Escolar | D16: 25 | E16: =IF($A16="","",SUMIFS('1_Compras_e_Inventario_Inicial'!$G$11:$G$510,'1_Compras_e_Inventario_Inicial'!$D$11:$D$510,$A16)) | F16: =IF($A16="","",SUMIFS('3_Ventas_Diarias'!$E$11:$E$610,'3_Ventas_Diarias'!$C$11:$C$610,$A16)) | G16: =IF($A16="","",N($D16)+N($E16)-N($F16)) | H16: 30 | I16: =IF($A16="","",IF($G16<=0,"🔴 SIN STOCK",IF($G16<=$H16,"🟠 REPONER",IF($G16<=$H16*1.5,"🟡 VIGILAR","🟢 OK")))) | J16: =IF($A16="","",IFERROR(SUMIFS('1_Compras_e_Inventario_Inicial'!$I$11:$I$510,'1_Compras_e_Inventario_Inicial'!$D$11:$D$510,$A16)/SUMIFS('1_Compras_e_Inventario_Inicial'!$G$11:$G$510,'1_Compras_e_Inventario_Inicial'!$D$11:$D$510,$A16),0)) | K16: 9.9 | L16: =IF($A16="","",$G16*$J16) | M16: =IF($A16="","",$G16*$K16) | N16: =IF($A16="","",IFERROR(($K16-$J16)/$K16,0))
A17: KAW-103 | B17: Peluche llavero ajolote | C17: Kawaii/Escolar | D17: 10 | E17: =IF($A17="","",SUMIFS('1_Compras_e_Inventario_Inicial'!$G$11:$G$510,'1_Compras_e_Inventario_Inicial'!$D$11:$D$510,$A17)) | F17: =IF($A17="","",SUMIFS('3_Ventas_Diarias'!$E$11:$E$610,'3_Ventas_Diarias'!$C$11:$C$610,$A17)) | G17: =IF($A17="","",N($D17)+N($E17)-N($F17)) | H17: 20 | I17: =IF($A17="","",IF($G17<=0,"🔴 SIN STOCK",IF($G17<=$H17,"🟠 REPONER",IF($G17<=$H17*1.5,"🟡 VIGILAR","🟢 OK")))) | J17: =IF($A17="","",IFERROR(SUMIFS('1_Compras_e_Inventario_Inicial'!$I$11:$I$510,'1_Compras_e_Inventario_Inicial'!$D$11:$D$510,$A17)/SUMIFS('1_Compras_e_Inventario_Inicial'!$G$11:$G$510,'1_Compras_e_Inventario_Inicial'!$D$11:$D$510,$A17),0)) | K17: 16.9 | L17: =IF($A17="","",$G17*$J17) | M17: =IF($A17="","",$G17*$K17) | N17: =IF($A17="","",IFERROR(($K17-$J17)/$K17,0))
A18: LIB-201 | B18: Libro infantil ilustrado | C18: Libros | D18: 8 | E18: =IF($A18="","",SUMIFS('1_Compras_e_Inventario_Inicial'!$G$11:$G$510,'1_Compras_e_Inventario_Inicial'!$D$11:$D$510,$A18)) | F18: =IF($A18="","",SUMIFS('3_Ventas_Diarias'!$E$11:$E$610,'3_Ventas_Diarias'!$C$11:$C$610,$A18)) | G18: =IF($A18="","",N($D18)+N($E18)-N($F18)) | H18: 12 | I18: =IF($A18="","",IF($G18<=0,"🔴 SIN STOCK",IF($G18<=$H18,"🟠 REPONER",IF($G18<=$H18*1.5,"🟡 VIGILAR","🟢 OK")))) | J18: =IF($A18="","",IFERROR(SUMIFS('1_Compras_e_Inventario_Inicial'!$I$11:$I$510,'1_Compras_e_Inventario_Inicial'!$D$11:$D$510,$A18)/SUMIFS('1_Compras_e_Inventario_Inicial'!$G$11:$G$510,'1_Compras_e_Inventario_Inicial'!$D$11:$D$510,$A18),0)) | K18: 29.9 | L18: =IF($A18="","",$G18*$J18) | M18: =IF($A18="","",$G18*$K18) | N18: =IF($A18="","",IFERROR(($K18-$J18)/$K18,0))
A19: LIB-202 | B19: Diccionario escolar | C19: Libros | D19: 5 | E19: =IF($A19="","",SUMIFS('1_Compras_e_Inventario_Inicial'!$G$11:$G$510,'1_Compras_e_Inventario_Inicial'!$D$11:$D$510,$A19)) | F19: =IF($A19="","",SUMIFS('3_Ventas_Diarias'!$E$11:$E$610,'3_Ventas_Diarias'!$C$11:$C$610,$A19)) | G19: =IF($A19="","",N($D19)+N($E19)-N($F19)) | H19: 8 | I19: =IF($A19="","",IF($G19<=0,"🔴 SIN STOCK",IF($G19<=$H19,"🟠 REPONER",IF($G19<=$H19*1.5,"🟡 VIGILAR","🟢 OK")))) | J19: =IF($A19="","",IFERROR(SUMIFS('1_Compras_e_Inventario_Inicial'!$I$11:$I$510,'1_Compras_e_Inventario_Inicial'!$D$11:$D$510,$A19)/SUMIFS('1_Compras_e_Inventario_Inicial'!$G$11:$G$510,'1_Compras_e_Inventario_Inicial'!$D$11:$D$510,$A19),0)) | K19: 34.9 | L19: =IF($A19="","",$G19*$J19) | M19: =IF($A19="","",$G19*$K19) | N19: =IF($A19="","",IFERROR(($K19-$J19)/$K19,0))
A20: LIB-203 | B20: Plan lector secundaria | C20: Libros | D20: 6 | E20: =IF($A20="","",SUMIFS('1_Compras_e_Inventario_Inicial'!$G$11:$G$510,'1_Compras_e_Inventario_Inicial'!$D$11:$D$510,$A20)) | F20: =IF($A20="","",SUMIFS('3_Ventas_Diarias'!$E$11:$E$610,'3_Ventas_Diarias'!$C$11:$C$610,$A20)) | G20: =IF($A20="","",N($D20)+N($E20)-N($F20)) | H20: 10 | I20: =IF($A20="","",IF($G20<=0,"🔴 SIN STOCK",IF($G20<=$H20,"🟠 REPONER",IF($G20<=$H20*1.5,"🟡 VIGILAR","🟢 OK")))) | J20: =IF($A20="","",IFERROR(SUMIFS('1_Compras_e_Inventario_Inicial'!$I$11:$I$510,'1_Compras_e_Inventario_Inicial'!$D$11:$D$510,$A20)/SUMIFS('1_Compras_e_Inventario_Inicial'!$G$11:$G$510,'1_Compras_e_Inventario_Inicial'!$D$11:$D$510,$A20),0)) | K20: 26.9 | L20: =IF($A20="","",$G20*$J20) | M20: =IF($A20="","",$G20*$K20) | N20: =IF($A20="","",IFERROR(($K20-$J20)/$K20,0))
A21: ART-301 | B21: Témpera 12 colores | C21: Arte | D21: 12 | E21: =IF($A21="","",SUMIFS('1_Compras_e_Inventario_Inicial'!$G$11:$G$510,'1_Compras_e_Inventario_Inicial'!$D$11:$D$510,$A21)) | F21: =IF($A21="","",SUMIFS('3_Ventas_Diarias'!$E$11:$E$610,'3_Ventas_Diarias'!$C$11:$C$610,$A21)) | G21: =IF($A21="","",N($D21)+N($E21)-N($F21)) | H21: 20 | I21: =IF($A21="","",IF($G21<=0,"🔴 SIN STOCK",IF($G21<=$H21,"🟠 REPONER",IF($G21<=$H21*1.5,"🟡 VIGILAR","🟢 OK")))) | J21: =IF($A21="","",IFERROR(SUMIFS('1_Compras_e_Inventario_Inicial'!$I$11:$I$510,'1_Compras_e_Inventario_Inicial'!$D$11:$D$510,$A21)/SUMIFS('1_Compras_e_Inventario_Inicial'!$G$11:$G$510,'1_Compras_e_Inventario_Inicial'!$D$11:$D$510,$A21),0)) | K21: 13.9 | L21: =IF($A21="","",$G21*$J21) | M21: =IF($A21="","",$G21*$K21) | N21: =IF($A21="","",IFERROR(($K21-$J21)/$K21,0))
A22: ART-302 | B22: Block de dibujo A3 | C22: Arte | D22: 15 | E22: =IF($A22="","",SUMIFS('1_Compras_e_Inventario_Inicial'!$G$11:$G$510,'1_Compras_e_Inventario_Inicial'!$D$11:$D$510,$A22)) | F22: =IF($A22="","",SUMIFS('3_Ventas_Diarias'!$E$11:$E$610,'3_Ventas_Diarias'!$C$11:$C$610,$A22)) | G22: =IF($A22="","",N($D22)+N($E22)-N($F22)) | H22: 20 | I22: =IF($A22="","",IF($G22<=0,"🔴 SIN STOCK",IF($G22<=$H22,"🟠 REPONER",IF($G22<=$H22*1.5,"🟡 VIGILAR","🟢 OK")))) | J22: =IF($A22="","",IFERROR(SUMIFS('1_Compras_e_Inventario_Inicial'!$I$11:$I$510,'1_Compras_e_Inventario_Inicial'!$D$11:$D$510,$A22)/SUMIFS('1_Compras_e_Inventario_Inicial'!$G$11:$G$510,'1_Compras_e_Inventario_Inicial'!$D$11:$D$510,$A22),0)) | K22: 10.9 | L22: =IF($A22="","",$G22*$J22) | M22: =IF($A22="","",$G22*$K22) | N22: =IF($A22="","",IFERROR(($K22-$J22)/$K22,0))
... A31: KAW-104 | B31: Cuaderno ajolote tapa dura A5 | C31: Kawaii/Escolar | D31: 0 | E31: =IF($A31="","",SUMIFS('1_Compras_e_Inventario_Inicial'!$G$11:$G$510,'1_Compras_e_Inventario_Inicial'!$D$11:$D$510,$A31)) | F31: =IF($A31="","",SUMIFS('3_Ventas_Diarias'!$E$11:$E$610,'3_Ventas_Diarias'!$C$11:$C$610,$A31)) | G31: =IF($A31="","",N($D31)+N($E31)-N($F31)) | H31: 12 | I31: =IF($A31="","",IF($G31<=0,"🔴 SIN STOCK",IF($G31<=$H31,"🟠 REPONER",IF($G31<=$H31*1.5,"🟡 VIGILAR","🟢 OK")))) | J31: =IF($A31="","",IFERROR(SUMIFS('1_Compras_e_Inventario_Inicial'!$I$11:$I$510,'1_Compras_e_Inventario_Inicial'!$D$11:$D$510,$A31)/SUMIFS('1_Compras_e_Inventario_Inicial'!$G$11:$G$510,'1_Compras_e_Inventario_Inicial'!$D$11:$D$510,$A31),0)) | K31: 22.9 | L31: =IF($A31="","",$G31*$J31) | M31: =IF($A31="","",$G31*$K31) | N31: =IF($A31="","",IFERROR(($K31-$J31)/$K31,0))
E32: =IF($A32="","",SUMIFS('1_Compras_e_Inventario_Inicial'!$G$11:$G$510,'1_Compras_e_Inventario_Inicial'!$D$11:$D$510,$A32)) | F32: =IF($A32="","",SUMIFS('3_Ventas_Diarias'!$E$11:$E$610,'3_Ventas_Diarias'!$C$11:$C$610,$A32)) | G32: =IF($A32="","",N($D32)+N($E32)-N($F32)) | I32: =IF($A32="","",IF($G32<=0,"🔴 SIN STOCK",IF($G32<=$H32,"🟠 REPONER",IF($G32<=$H32*1.5,"🟡 VIGILAR","🟢 OK")))) | J32: =IF($A32="","",IFERROR(SUMIFS('1_Compras_e_Inventario_Inicial'!$I$11:$I$510,'1_Compras_e_Inventario_Inicial'!$D$11:$D$510,$A32)/SUMIFS('1_Compras_e_Inventario_Inicial'!$G$11:$G$510,'1_Compras_e_Inventario_Inicial'!$D$11:$D$510,$A32),0)) | L32: =IF($A32="","",$G32*$J32) | M32: =IF($A32="","",$G32*$K32) | N32: =IF($A32="","",IFERROR(($K32-$J32)/$K32,0))
E33: =IF($A33="","",SUMIFS('1_Compras_e_Inventario_Inicial'!$G$11:$G$510,'1_Compras_e_Inventario_Inicial'!$D$11:$D$510,$A33)) | F33: =IF($A33="","",SUMIFS('3_Ventas_Diarias'!$E$11:$E$610,'3_Ventas_Diarias'!$C$11:$C$610,$A33)) | G33: =IF($A33="","",N($D33)+N($E33)-N($F33)) | I33: =IF($A33="","",IF($G33<=0,"🔴 SIN STOCK",IF($G33<=$H33,"🟠 REPONER",IF($G33<=$H33*1.5,"🟡 VIGILAR","🟢 OK")))) | J33: =IF($A33="","",IFERROR(SUMIFS('1_Compras_e_Inventario_Inicial'!$I$11:$I$510,'1_Compras_e_Inventario_Inicial'!$D$11:$D$510,$A33)/SUMIFS('1_Compras_e_Inventario_Inicial'!$G$11:$G$510,'1_Compras_e_Inventario_Inicial'!$D$11:$D$510,$A33),0)) | L33: =IF($A33="","",$G33*$J33) | M33: =IF($A33="","",$G33*$K33) | N33: =IF($A33="","",IFERROR(($K33-$J33)/$K33,0))
E34: =IF($A34="","",SUMIFS('1_Compras_e_Inventario_Inicial'!$G$11:$G$510,'1_Compras_e_Inventario_Inicial'!$D$11:$D$510,$A34)) | F34: =IF($A34="","",SUMIFS('3_Ventas_Diarias'!$E$11:$E$610,'3_Ventas_Diarias'!$C$11:$C$610,$A34)) | G34: =IF($A34="","",N($D34)+N($E34)-N($F34)) | I34: =IF($A34="","",IF($G34<=0,"🔴 SIN STOCK",IF($G34<=$H34,"🟠 REPONER",IF($G34<=$H34*1.5,"🟡 VIGILAR","🟢 OK")))) | J34: =IF($A34="","",IFERROR(SUMIFS('1_Compras_e_Inventario_Inicial'!$I$11:$I$510,'1_Compras_e_Inventario_Inicial'!$D$11:$D$510,$A34)/SUMIFS('1_Compras_e_Inventario_Inicial'!$G$11:$G$510,'1_Compras_e_Inventario_Inicial'!$D$11:$D$510,$A34),0)) | L34: =IF($A34="","",$G34*$J34) | M34: =IF($A34="","",$G34*$K34) | N34: =IF($A34="","",IFERROR(($K34-$J34)/$K34,0))
E35: =IF($A35="","",SUMIFS('1_Compras_e_Inventario_Inicial'!$G$11:$G$510,'1_Compras_e_Inventario_Inicial'!$D$11:$D$510,$A35)) | F35: =IF($A35="","",SUMIFS('3_Ventas_Diarias'!$E$11:$E$610,'3_Ventas_Diarias'!$C$11:$C$610,$A35)) | G35: =IF($A35="","",N($D35)+N($E35)-N($F35)) | I35: =IF($A35="","",IF($G35<=0,"🔴 SIN STOCK",IF($G35<=$H35,"🟠 REPONER",IF($G35<=$H35*1.5,"🟡 VIGILAR","🟢 OK")))) | J35: =IF($A35="","",IFERROR(SUMIFS('1_Compras_e_Inventario_Inicial'!$I$11:$I$510,'1_Compras_e_Inventario_Inicial'!$D$11:$D$510,$A35)/SUMIFS('1_Compras_e_Inventario_Inicial'!$G$11:$G$510,'1_Compras_e_Inventario_Inicial'!$D$11:$D$510,$A35),0)) | L35: =IF($A35="","",$G35*$J35) | M35: =IF($A35="","",$G35*$K35) | N35: =IF($A35="","",IFERROR(($K35-$J35)/$K35,0))
E36: =IF($A36="","",SUMIFS('1_Compras_e_Inventario_Inicial'!$G$11:$G$510,'1_Compras_e_Inventario_Inicial'!$D$11:$D$510,$A36)) | F36: =IF($A36="","",SUMIFS('3_Ventas_Diarias'!$E$11:$E$610,'3_Ventas_Diarias'!$C$11:$C$610,$A36)) | G36: =IF($A36="","",N($D36)+N($E36)-N($F36)) | I36: =IF($A36="","",IF($G36<=0,"🔴 SIN STOCK",IF($G36<=$H36,"🟠 REPONER",IF($G36<=$H36*1.5,"🟡 VIGILAR","🟢 OK")))) | J36: =IF($A36="","",IFERROR(SUMIFS('1_Compras_e_Inventario_Inicial'!$I$11:$I$510,'1_Compras_e_Inventario_Inicial'!$D$11:$D$510,$A36)/SUMIFS('1_Compras_e_Inventario_Inicial'!$G$11:$G$510,'1_Compras_e_Inventario_Inicial'!$D$11:$D$510,$A36),0)) | L36: =IF($A36="","",$G36*$J36) | M36: =IF($A36="","",$G36*$K36) | N36: =IF($A36="","",IFERROR(($K36-$J36)/$K36,0))
E37: =IF($A37="","",SUMIFS('1_Compras_e_Inventario_Inicial'!$G$11:$G$510,'1_Compras_e_Inventario_Inicial'!$D$11:$D$510,$A37)) | F37: =IF($A37="","",SUMIFS('3_Ventas_Diarias'!$E$11:$E$610,'3_Ventas_Diarias'!$C$11:$C$610,$A37)) | G37: =IF($A37="","",N($D37)+N($E37)-N($F37)) | I37: =IF($A37="","",IF($G37<=0,"🔴 SIN STOCK",IF($G37<=$H37,"🟠 REPONER",IF($G37<=$H37*1.5,"🟡 VIGILAR","🟢 OK")))) | J37: =IF($A37="","",IFERROR(SUMIFS('1_Compras_e_Inventario_Inicial'!$I$11:$I$510,'1_Compras_e_Inventario_Inicial'!$D$11:$D$510,$A37)/SUMIFS('1_Compras_e_Inventario_Inicial'!$G$11:$G$510,'1_Compras_e_Inventario_Inicial'!$D$11:$D$510,$A37),0)) | L37: =IF($A37="","",$G37*$J37) | M37: =IF($A37="","",$G37*$K37) | N37: =IF($A37="","",IFERROR(($K37-$J37)/$K37,0))
E38: =IF($A38="","",SUMIFS('1_Compras_e_Inventario_Inicial'!$G$11:$G$510,'1_Compras_e_Inventario_Inicial'!$D$11:$D$510,$A38)) | F38: =IF($A38="","",SUMIFS('3_Ventas_Diarias'!$E$11:$E$610,'3_Ventas_Diarias'!$C$11:$C$610,$A38)) | G38: =IF($A38="","",N($D38)+N($E38)-N($F38)) | I38: =IF($A38="","",IF($G38<=0,"🔴 SIN STOCK",IF($G38<=$H38,"🟠 REPONER",IF($G38<=$H38*1.5,"🟡 VIGILAR","🟢 OK")))) | J38: =IF($A38="","",IFERROR(SUMIFS('1_Compras_e_Inventario_Inicial'!$I$11:$I$510,'1_Compras_e_Inventario_Inicial'!$D$11:$D$510,$A38)/SUMIFS('1_Compras_e_Inventario_Inicial'!$G$11:$G$510,'1_Compras_e_Inventario_Inicial'!$D$11:$D$510,$A38),0)) | L38: =IF($A38="","",$G38*$J38) | M38: =IF($A38="","",$G38*$K38) | N38: =IF($A38="","",IFERROR(($K38-$J38)/$K38,0))
E39: =IF($A39="","",SUMIFS('1_Compras_e_Inventario_Inicial'!$G$11:$G$510,'1_Compras_e_Inventario_Inicial'!$D$11:$D$510,$A39)) | F39: =IF($A39="","",SUMIFS('3_Ventas_Diarias'!$E$11:$E$610,'3_Ventas_Diarias'!$C$11:$C$610,$A39)) | G39: =IF($A39="","",N($D39)+N($E39)-N($F39)) | I39: =IF($A39="","",IF($G39<=0,"🔴 SIN STOCK",IF($G39<=$H39,"🟠 REPONER",IF($G39<=$H39*1.5,"🟡 VIGILAR","🟢 OK")))) | J39: =IF($A39="","",IFERROR(SUMIFS('1_Compras_e_Inventario_Inicial'!$I$11:$I$510,'1_Compras_e_Inventario_Inicial'!$D$11:$D$510,$A39)/SUMIFS('1_Compras_e_Inventario_Inicial'!$G$11:$G$510,'1_Compras_e_Inventario_Inicial'!$D$11:$D$510,$A39),0)) | L39: =IF($A39="","",$G39*$J39) | M39: =IF($A39="","",$G39*$K39) | N39: =IF($A39="","",IFERROR(($K39-$J39)/$K39,0))
E40: =IF($A40="","",SUMIFS('1_Compras_e_Inventario_Inicial'!$G$11:$G$510,'1_Compras_e_Inventario_Inicial'!$D$11:$D$510,$A40)) | F40: =IF($A40="","",SUMIFS('3_Ventas_Diarias'!$E$11:$E$610,'3_Ventas_Diarias'!$C$11:$C$610,$A40)) | G40: =IF($A40="","",N($D40)+N($E40)-N($F40)) | I40: =IF($A40="","",IF($G40<=0,"🔴 SIN STOCK",IF($G40<=$H40,"🟠 REPONER",IF($G40<=$H40*1.5,"🟡 VIGILAR","🟢 OK")))) | J40: =IF($A40="","",IFERROR(SUMIFS('1_Compras_e_Inventario_Inicial'!$I$11:$I$510,'1_Compras_e_Inventario_Inicial'!$D$11:$D$510,$A40)/SUMIFS('1_Compras_e_Inventario_Inicial'!$G$11:$G$510,'1_Compras_e_Inventario_Inicial'!$D$11:$D$510,$A40),0)) | L40: =IF($A40="","",$G40*$J40) | M40: =IF($A40="","",$G40*$K40) | N40: =IF($A40="","",IFERROR(($K40-$J40)/$K40,0))
E41: =IF($A41="","",SUMIFS('1_Compras_e_Inventario_Inicial'!$G$11:$G$510,'1_Compras_e_Inventario_Inicial'!$D$11:$D$510,$A41)) | F41: =IF($A41="","",SUMIFS('3_Ventas_Diarias'!$E$11:$E$610,'3_Ventas_Diarias'!$C$11:$C$610,$A41)) | G41: =IF($A41="","",N($D41)+N($E41)-N($F41)) | I41: =IF($A41="","",IF($G41<=0,"🔴 SIN STOCK",IF($G41<=$H41,"🟠 REPONER",IF($G41<=$H41*1.5,"🟡 VIGILAR","🟢 OK")))) | J41: =IF($A41="","",IFERROR(SUMIFS('1_Compras_e_Inventario_Inicial'!$I$11:$I$510,'1_Compras_e_Inventario_Inicial'!$D$11:$D$510,$A41)/SUMIFS('1_Compras_e_Inventario_Inicial'!$G$11:$G$510,'1_Compras_e_Inventario_Inicial'!$D$11:$D$510,$A41),0)) | L41: =IF($A41="","",$G41*$J41) | M41: =IF($A41="","",$G41*$K41) | N41: =IF($A41="","",IFERROR(($K41-$J41)/$K41,0))
E42: =IF($A42="","",SUMIFS('1_Compras_e_Inventario_Inicial'!$G$11:$G$510,'1_Compras_e_Inventario_Inicial'!$D$11:$D$510,$A42)) | F42: =IF($A42="","",SUMIFS('3_Ventas_Diarias'!$E$11:$E$610,'3_Ventas_Diarias'!$C$11:$C$610,$A42)) | G42: =IF($A42="","",N($D42)+N($E42)-N($F42)) | I42: =IF($A42="","",IF($G42<=0,"🔴 SIN STOCK",IF($G42<=$H42,"🟠 REPONER",IF($G42<=$H42*1.5,"🟡 VIGILAR","🟢 OK")))) | J42: =IF($A42="","",IFERROR(SUMIFS('1_Compras_e_Inventario_Inicial'!$I$11:$I$510,'1_Compras_e_Inventario_Inicial'!$D$11:$D$510,$A42)/SUMIFS('1_Compras_e_Inventario_Inicial'!$G$11:$G$510,'1_Compras_e_Inventario_Inicial'!$D$11:$D$510,$A42),0)) | L42: =IF($A42="","",$G42*$J42) | M42: =IF($A42="","",$G42*$K42) | N42: =IF($A42="","",IFERROR(($K42-$J42)/$K42,0))
E43: =IF($A43="","",SUMIFS('1_Compras_e_Inventario_Inicial'!$G$11:$G$510,'1_Compras_e_Inventario_Inicial'!$D$11:$D$510,$A43)) | F43: =IF($A43="","",SUMIFS('3_Ventas_Diarias'!$E$11:$E$610,'3_Ventas_Diarias'!$C$11:$C$610,$A43)) | G43: =IF($A43="","",N($D43)+N($E43)-N($F43)) | I43: =IF($A43="","",IF($G43<=0,"🔴 SIN STOCK",IF($G43<=$H43,"🟠 REPONER",IF($G43<=$H43*1.5,"🟡 VIGILAR","🟢 OK")))) | J43: =IF($A43="","",IFERROR(SUMIFS('1_Compras_e_Inventario_Inicial'!$I$11:$I$510,'1_Compras_e_Inventario_Inicial'!$D$11:$D$510,$A43)/SUMIFS('1_Compras_e_Inventario_Inicial'!$G$11:$G$510,'1_Compras_e_Inventario_Inicial'!$D$11:$D$510,$A43),0)) | L43: =IF($A43="","",$G43*$J43) | M43: =IF($A43="","",$G43*$K43) | N43: =IF($A43="","",IFERROR(($K43-$J43)/$K43,0))
... E210: =IF($A210="","",SUMIFS('1_Compras_e_Inventario_Inicial'!$G$11:$G$510,'1_Compras_e_Inventario_Inicial'!$D$11:$D$510,$A210)) | F210: =IF($A210="","",SUMIFS('3_Ventas_Diarias'!$E$11:$E$610,'3_Ventas_Diarias'!$C$11:$C$610,$A210)) | G210: =IF($A210="","",N($D210)+N($E210)-N($F210)) | I210: =IF($A210="","",IF($G210<=0,"🔴 SIN STOCK",IF($G210<=$H210,"🟠 REPONER",IF($G210<=$H210*1.5,"🟡 VIGILAR","🟢 OK")))) | J210: =IF($A210="","",IFERROR(SUMIFS('1_Compras_e_Inventario_Inicial'!$I$11:$I$510,'1_Compras_e_Inventario_Inicial'!$D$11:$D$510,$A210)/SUMIFS('1_Compras_e_Inventario_Inicial'!$G$11:$G$510,'1_Compras_e_Inventario_Inicial'!$D$11:$D$510,$A210),0)) | L210: =IF($A210="","",$G210*$J210) | M210: =IF($A210="","",$G210*$K210) | N210: =IF($A210="","",IFERROR(($K210-$J210)/$K210,0))

Sheet 3_Ventas_Diarias
A1: DAMABIS · Ventas Diarias Registro de ticket por ticket · Costo y ganancia automáticos
A6: 🛍️ VENTAS ACUMULADAS | C6: 💚 GANANCIA BRUTA | E6: 📦 UNIDADES VENDIDAS | G6: 🎟️ TICKET PROMEDIO | I6: 📊 MARGEN SOBRE VENTAS
